Workbook

Sheet Energy Audit Invoice
A1: ENERGY EFFICIENCY SERVICES of WISCONSIN
A2: 112 Owen Rd. PO Box 6141 | Monona, WI 53716 | 608-460-7419
A4: Invoice No.: | C4: INV-WI- | E4: Invoice Date: | G4: Invoice Date
E5: Due Date: | G5: Net 30
A9: Customer & Property Installation Information
A11: Property Owner: | F11: Property Name:
A12: Owner Address: | F12: Installation Address:
B13: City, State Zip | F13: City, State Zip:
A14: Contact Name: | F14: Property Type: | I14: Multifamily
A15: Email: | F15: IQ Number:
A16: Phone:
A18: Audit Services
A19: Registered Contractor Name: | C19: Energy Efficiency Services of Wisconsin
A20: # | B20: Service Description | I20: Qty | J20: Unit | K20: Unit Rate ($) | L20: Total
A21: 1 | B21: Whole-Building Energy Audit — Multifamily | I21: 1 | J21: Building | K21: 2000 | L21: =IF(ISNUMBER(I21),I21*K21,K21) -> 2000
A22: 2 | B22: Per-Unit Blower Door and Diagnostic Testing | J22: Unit | K22: included | L22: =IF(ISNUMBER(I22),I22*K22,K22) -> included
A23: 3 | B23: Common Area and Building Envelope Assessment | I23: 1 | J23: Lump Sum | K23: included | L23: =IF(ISNUMBER(I23),I23*K23,K23) -> included
A24: 4 | B24: Mechanical Systems Survey | I24: 1 | J24: Lump Sum | K24: included | L24: =IF(ISNUMBER(I24),I24*K24,K24) -> included
J25: Gross Total | L25: =SUM(L21:L24) -> 2000
I26: Non-IRA Rebates* | K26: =SUM(J41:J44) -> 0
I27: IRA Rebates* | K27: =SUM(J45:J46) -> 2000
J28: Total Rebates | L28: =-SUM(K26:K27) -> -2000
J29: TOTAL DUE | L29: =L25+L28 -> 0
A32: Deliverables
A33: # | B33: Deliverable | H33: Start Date | J33: End Date | K33: Notes
A34: 1 | B34: Whole-Building Energy Audit Report (ASHRAE Level II equivalent)
A35: 2 | B35: HPXML v4/Building Sync File from Asset Score
A36: 3 | B36: Customer Report / Building Assessment Tool Report
A39: *Rebates & Incentives
B40: Program | F40: Incentive Desciption | J40: Amount | K40: Notes
A41: NON-IRA | B41: Focus on Energy - Instant Discount
B42: Focus on Energy - Other
B43: Utility Rebate - Midstream Instant Discount
B44: Utility Rebate - Other
A45: IRA | B45: IRA HOMES Incentive - Instant Discount | F45: IQ MF Audit Rebate/Building | J45: 2000
B46: IRA HOMES Incentive - Other
A48: REBATE ASSIGNMENT NOTICE: TheWisconsin IRA rebate reflected above has been assigned by the property owner to Energy Efficiency Services, Inc. (EES-WI) and will be applied directly to reduce this invoice. Owner is not required to front or await reimbursement of the assigned rebate amount.
A51: Additional Notes:
A54: Acknowledgment & Acceptance
A55: Receipt of this invoice constitutes acknowledgment of the services delivered. The property owner confirms the work performed and authorizes EES-WI to submit for and receive the corresponding program incentive on their behalf.
...

Sheet HOMES Proposal-Contract
A1: ENERGY EFFICIENCY SERVICES of WISCONSIN
A2: 112 Owen Rd. PO Box 6141 | Monona, WI 53716 | 608-460-7419
A4: Proposal No.: | C4: HOMES-MF- | E4: Date: | G4: Proposal Date
E5: Valid for: | G5: 30 days
A9: Customer & Property Installation Information
A11: Property Owner: | C11: ='Energy Audit Invoice'!C11 -> 0 | F11: Property Name: | I11: ='Energy Audit Invoice'!I11 -> 0
A12: Owner Address: | C12: ='Energy Audit Invoice'!C12 -> 0 | F12: Installation Address: | I12: ='Energy Audit Invoice'!I12 -> 0
B13: City, State Zip | C13: ='Energy Audit Invoice'!C13 -> 0 | F13: City, State Zip: | I13: ='Energy Audit Invoice'!I13 -> 0
A14: Contact Name: | C14: ='Energy Audit Invoice'!C14 -> 0 | F14: Property Type: | I14: Multifamily
A15: Email: | C15: ='Energy Audit Invoice'!C15 -> 0 | F15: IQ Number: | I15: ='Energy Audit Invoice'!I15 -> 0
A16: Phone: | C16: ='Energy Audit Invoice'!C16 -> 0
N17: Number of Units: | P17: 11 | Q17: <<------ | R17: Enter
A18: Proposed Scope of Work - HOMES PROJECT | N18: Homes Rebate: | P18: =P17*10000 -> 110000
A19: Estimated Start Date: | F19: Estimated Completion Date: | N19: FOE Rebate: | P19: =SUM(J40:J43) -> 0
A20: Registered Contractor Name: | C20: Energy Efficiency Services of Wisconsin | N20: Total Rebate: | P20: =SUM(P18:P19) -> 110000
A21: # | B21: Measure Line Item | D21: Measure Description | I21: Qty | K21: Unit | L21: Cost | N21: Breakout*:
A22: 1 | B22: Attic Insulation | K22: Sq Ft | L22: =P22 -> 48400 | O22: 0.44 | P22: =$P$20*O22 -> 48400
A23: 2 | B23: Attic Air Sealing | K23: Sq Ft | L23: =P23 -> 60313 | O23: 0.5483 | P23: =$P$20*O23 -> 60313
A24: 3 | B24: Low Flow Devices: Bath Aerators | K24: Unit | L24: =P24 -> 363 | O24: 0.0033 | P24: =$P$20*O24 -> 363
A25: 4 | B25: Low Flow Devices: Kitchen Aerators | K25: Unit | L25: =P25 -> 385 | O25: 0.0035 | P25: =$P$20*O25 -> 385
A26: 5 | B26: Low Flow Devices: Showerheads | K26: Unit | L26: =P26 -> 539 | O26: 0.0049 | P26: =$P$20*O26 -> 539
A27: 6 | B27: Energy Star Ventilation | I27: =P19 -> 0 | K27: Unit | L27: =P27 -> 0 | P27: =$P$20*O27 -> 0
A28: 7 | B28: Energy Star Heating & Cooling Equipment | I28: =P19 -> 0 | K28: Unit | L28: =P28 -> 0 | P28: =$P$20*O28 -> 0
A29: 8 | B29: Energy Star Appliances | I29: =P19 -> 0 | K29: Unit | L29: =P29 -> 0 | P29: =$P$20*O29 -> 0
I30: Gross Total | L30: =SUM(L22:L29) -> 110000 | O30: =SUM(O22:O29) -> 1 | P30: =SUM(P22:P29) -> 110000 | Q30: Needs to Equal P19
I31: Non-IRA Rebates* | K31: =SUM(J40:J43) -> 0
I32: IRA Rebates* | K32: =SUM(J44:J45) -> 110000
J33: Total Rebates | L33: =-SUM(K31:K32) -> -110000
I34: TOTAL DUE | L34: =L30+L33 -> 0
A38: Applicable Rebates & Incentives
B39: Program | D39: Incentive Desciption | J39: Amount | K39: Notes
A40: NON-IRA | B40: Focus on Energy - Instant Discount | J40: =0.7*I22 -> 0 | K40: $0.55 per Sq. Ft.
B41: Focus on Energy - Other
B42: Utility Rebate - Instant Discount
B43: Utility Rebate - Other
A44: IRA | B44: IRA HOMES - Instant Discount | D44: IQ at <80% AMI and modeled energy savings of 35% or greater | J44: =P18 -> 110000 | K44: $10,000.00 per unit
B45: IRA HOMES - Other
A47: REBATE ASSIGNMENT NOTICE: TheWisconsin IRA rebate reflected above will be assigned by the property owner to Energy Efficiency Services, Inc. (EES-WI) and will be applied directly to reduce the future invoice. Owner is not required to front or await reimbursement of the assigned rebate amount.
A50: Additional Notes:
A53: Acknowledgment & Acceptance
...

Sheet HOMES Project Invoice
A1: ENERGY EFFICIENCY SERVICES of WISCONSIN
A2: 112 Owen Rd. PO Box 6141 | Monona, WI 53716 | 608-460-7419
A4: Invoice No.: | C4: EST-WI- | E4: Invoice Date: | G4: Invoice Date
E5: Due Date: | G5: 30 days
A9: Customer & Property Installation Information
A11: Property Owner: | C11: ='Energy Audit Invoice'!C11 -> 0 | F11: Property Name: | I11: ='Energy Audit Invoice'!I11 -> 0
A12: Owner Address: | C12: ='Energy Audit Invoice'!C12 -> 0 | F12: Installation Address: | I12: ='Energy Audit Invoice'!I12 -> 0
B13: City, State Zip | C13: ='Energy Audit Invoice'!C13 -> 0 | F13: City, State Zip: | I13: ='Energy Audit Invoice'!I13 -> 0
A14: Contact Name: | C14: ='Energy Audit Invoice'!C14 -> 0 | F14: Property Type: | I14: Multifamily
A15: Email: | C15: ='Energy Audit Invoice'!C15 -> 0 | F15: IQ Number: | I15: ='Energy Audit Invoice'!I15 -> 0
A16: Phone: | C16: ='Energy Audit Invoice'!C16 -> 0 | N16: INVOICE AMOUNTS MUST MATCH THE PROPOSAL!!
N17: Number of Units: | P17: 8 | Q17: <<------ | R17: Enter
A18: Installed Scope of Work - HOMES PROJECT | N18: Homes Rebate: | P18: =P17*10000 -> 80000
A19: Start Date: | F19: Completion Date: | N19: FOE Rebate: | P19: =SUM(J40:J43) -> 0
A20: Registered Contractor Name: | C20: Energy Efficiency Services of Wisconsin | N20: Total Rebate: | P20: =SUM(P18:P19) -> 80000
A21: # | B21: Measure Line Item | D21: Measure Description | I21: Qty | K21: Unit | L21: Cost | N21: Breakout*:
A22: 1 | B22: Attic Insulation | K22: Sq Ft | L22: =P22 -> 0 | O22: 0.44 | P22: =$P$20*O22 -> 0
A23: 2 | B23: Attic Air Sealing | K23: Sq Ft | L23: =P23 -> 0 | O23: 0.5483 | P23: =$P$20*O23 -> 0
A24: 3 | B24: Low Flow Devices: Bath Aerators | K24: Unit | L24: =P24 -> 0 | O24: 0.0033 | P24: =$P$20*O24 -> 0
A25: 4 | B25: Low Flow Devices: Kitchen Aerators | K25: Unit | L25: =P25 -> 0 | O25: 0.0035 | P25: =$P$20*O25 -> 0
A26: 5 | B26: Low Flow Devices: Showerheads | K26: Unit | L26: =P26 -> 0 | O26: 0.0049 | P26: =$P$20*O26 -> 0
A27: 6 | B27: Energy Star Ventilation | K27: Unit | L27: =P27 -> 0 | P27: =$P$20*O27 -> 0
A28: 7 | B28: Energy Star Heating & Cooling Equipment | K28: Unit | L28: =P28 -> 0 | P28: =$P$20*O28 -> 0
A29: 8 | B29: Energy Star Appliances | K29: Unit | L29: =P29 -> 0 | P29: =$P$20*O29 -> 0
I30: Gross Total | L30: =SUM(L22:L29) -> 0 | O30: =SUM(O22:O29) -> 1 | P30: =SUM(P22:P29) -> 0 | Q30: Needs to Equal P19
I31: Non-IRA Rebates* | K31: =SUM(J40:J43) -> 0
I32: IRA Rebates* | K32: =SUM(J44:J45) -> 80000
J33: Total Rebates | L33: =-SUM(K31:K32) -> -80000
I34: TOTAL DUE | L34: =L30+L33 -> -80000
A38: Applicable Rebates & Incentives
B39: Program | D39: Incentive Desciption | J39: Amount | K39: Notes
A40: NON-IRA | B40: Focus on Energy - Instant Discount | J40: =0.55*I22 -> 0 | K40: $0.55 per Sq. Ft.
B41: Focus on Energy - Other
B42: Utility Rebate - Instant Discount
B43: Utility Rebate - Other
A44: IRA | B44: IRA HOMES - Instant Discount | J44: =P18 -> 80000 | K44: $10,000.00 per unit
B45: IRA HOMES - Other
A47: REBATE ASSIGNMENT NOTICE: TheWisconsin IRA rebate reflected above has been assigned by the property owner to Energy Efficiency Services, Inc. (EES-WI) and will be applied directly to reduce this invoice. Owner is not required to front or await reimbursement of the assigned rebate amount.
A50: Additional Notes:
A53: Acknowledgment & Acceptance
...

Sheet HEAR Proposal-Contract
A1: ENERGY EFFICIENCY SERVICES of WISCONSIN
A2: 112 Owen Rd. PO Box 6141 | Monona, WI 53716 | 608-460-7419
A4: Proposal No.: | C4: HEAR-MF- | E4: Date: | G4: Proposal Date
E5: Valid for: | G5: 30 days
A9: Customer & Property Installation Information
A11: Property Owner: | C11: ='Energy Audit Invoice'!C11 -> 0 | F11: Property Name: | I11: ='Energy Audit Invoice'!I11 -> 0
A12: Owner Address: | C12: ='Energy Audit Invoice'!C12 -> 0 | F12: Installation Address: | I12: ='Energy Audit Invoice'!I12 -> 0
B13: City, State Zip | C13: ='Energy Audit Invoice'!C13 -> 0 | F13: City, State Zip: | I13: ='Energy Audit Invoice'!I13 -> 0
A14: Contact Name: | C14: ='Energy Audit Invoice'!C14 -> 0 | F14: Property Type: | I14: Multifamily
A15: Email: | C15: ='Energy Audit Invoice'!C15 -> 0 | F15: IQ Number: | I15: ='Energy Audit Invoice'!I15 -> 0
A16: Phone: | C16: ='Energy Audit Invoice'!C16 -> 0
N17: Number of Units: | Q17: <<------ | R17: Enter
A18: Proposed Scope of Work - HOMES PROJECT | N18: Homes Rebate: | P18: =P17*10000 -> 0
A19: Estimated Start Date: | F19: Estimated Completion Date: | N19: FOE Rebate: | P19: =I22*0.55 -> 0
A20: Registered Contractor Name: | C20: Energy Efficiency Services of Wisconsin | N20: Total Rebate: | P20: =SUM(P18:P19) -> 0
A21: # | B21: Measure Line Item | D21: Measure Description | I21: Qty | K21: Unit | L21: Cost | N21: Breakout*:
A22: 1 | B22: ENERGY STAR® electric heat pump water heater | I22: =P17 -> 0 | K22: Unit | O22: 0.44 | P22: =$P$20*O22 -> 0
A23: 2 | B23: ENERGY STAR electric heat pump for space heating and cooling | I23: =P18 -> 0 | K23: Unit | O23: 0.5483 | P23: =$P$20*O23 -> 0
A24: 3 | B24: Electrical load service center (electrical panel) | I24: =P19 -> 0 | K24: Unit | O24: 0.0033 | P24: =$P$20*O24 -> 0
A25: 4 | B25: Electrical Wiring | I25: =P19 -> 0 | K25: Unit | O25: 0.0035 | P25: =$P$20*O25 -> 0
A26: 5 | B26: ENERGY STAR ventilation | I26: =P19 -> 0 | K26: Unit | O26: 0.0049 | P26: =$P$20*O26 -> 0
A27: 6 | B27: ENERGY STAR electric heat pump clothes dryer | I27: =P19 -> 0 | K27: Unit | P27: =$P$20*O27 -> 0
A28: 7 | B28: ENERGY STAR electric stove, ENERGY STAR cooktop, ENERGY STAR range* | I28: =P19 -> 0 | K28: Unit | P28: =$P$20*O28 -> 0
I29: Gross Total | L29: =SUM(L22:L28) -> 0 | O29: =SUM(O22:O28) -> 1 | P29: =SUM(P22:P28) -> 0 | Q29: Needs to Equal P19
I30: Non-IRA Rebates* | K30: =SUM(J39:J42) -> 900
I31: IRA Rebates* | K31: =SUM(J45:J46) -> 0 | P31: HEAR Rebate | Q31: Measure
J32: Total Rebates | L32: =-SUM(K30:K31) -> -900 | P32: 1750 | Q32: ENERGY STAR® electric heat pump water heater
I33: TOTAL DUE | L33: =L29+L32 -> -900 | P33: 8000 | Q33: ENERGY STAR electric heat pump for space heating and cooling
P34: 4000 | Q34: Electrical load service center (electrical panel)
P35: 2500 | Q35: Electrical Wiring
P36: 1600 | Q36: ENERGY STAR ventilation
A37: Applicable Rebates & Incentives | P37: 840 | Q37: ENERGY STAR electric heat pump clothes dryer
B38: Program | D38: Incentive Desciption | J38: Amount | K38: Notes | P38: 840 | Q38: ENERGY STAR electric stove, ENERGY STAR cooktop, ENERGY STAR range*
A39: NON-IRA | B39: Focus on Energy - Instant Discount | D39: Midstream HP Tier 4 (16.0 SEER2, 10.0 HSPF2) | J39: 900
B40: Focus on Energy - Other
B41: Utility Rebate - Instant Discount
B42: Utility Rebate - Other
A43: IRA | B43: IRA HOMES - Instant Discount
B44: IRA HOMES - Instant Discount
B45: IRA HOMES - Instant Discount
...

Sheet Resources
A1: FOCUS ON ENERY WEATHERIZATION REBATES
A2: SINGLE FAMILY HOMES | F2: MULTIFAMILY BUILDINGS
A3: Single-Family Home (1-3 Units) Insulation and Air Sealing | B3: Rebate for Higher-Income Households (Above 150% Area Median Income (AMI)) | C3: Rebate for Moderate-Income Households (Between 80% and 150% AMI) | D3: Rebate for Low-Income Households (Below 80% AMI) | F3: Insulation & Air Sealing Multifamily Home (4+units) | G3: Rebate
A4: ENERGY STAR® Qualified Air Sealing Energy assessment required.* | B4: 850 | C4: 1160 | D4: 1475 | F4: Air Sealing & Attic Insulation, Existing < R-11 | G4: $1.00 per sq. ft. of attic space
A5: Attic Insulation | B5: 650 | C5: 750 | D5: 850 | F5: Air Sealing & Attic Insulation, Existing R-12 to R-19 | G5: $0.70 per sq. ft of attic space
A6: Foundation Insulation | B6: 90 | C6: 120 | D6: 150 | F6: Air Sealing & Attic Insulation, Existing R-20 to R-38 | G6: $0.55 per sq. ft of attic space
A7: Sill Insulation | B7: 90 | C7: 120 | D7: 150 | F7: Exterior Wall Insulation, Existing <R5 | G7: $0.80 per sq. ft of wall area improved
A8: Wall Insulation | B8: 575 | C8: 575 | D8: 575
A9: Seal and Insulate Ducts in a Semi-Conditioned Space | B9: 90 | C9: 90 | D9: 90
A10: Seal and Insulation Ducts in an Unconditioned Space | B10: 1000 | C10: 1000 | D10: 1000
A11: DIY Attic Insulation & Air Sealing | B11: 200 | C11: 200 | D11: 200
A13: *Must be completed along with Trade Ally contractor-installed attic or wall insulation improvements. Please review the Program Requirements tab for full participation requirements.
A17: HEAR Upgrade | B17: Rebate Max Per Product Category | C17: Registered Contractor or Store | D17: Eligible for New Construction
A18: ENERGY STAR® electric heat pump water heater | B18: Up to $1,750 | C18: Registered Contractor or Store Purchase | D18: Yes
A19: ENERGY STAR electric heat pump for space heating and cooling | B19: Up to $8,000 | C19: Registered Contractor | D19: Yes
A20: Electrical load service center (electrical panel) | B20: Up to $4,000 | C20: Registered Contractor | D20: No
A21: Electrical Wiring | B21: Up to $2,500 | C21: Registered Contractor | D21: No
A22: ENERGY STAR Insulation, ENERGY STAR ventilation, air sealing | B22: Up to $1,600 | C22: Registered Contractor | D22: No
A23: ENERGY STAR electric heat pump clothes dryer | B23: Up to $840 | C23: Store Purchase | D23: Yes
A24: ENERGY STAR electric stove, ENERGY STAR cooktop, ENERGY STAR range* | B24: Up to $840 | C24: Store Purchase | D24: Yes

Sheet Measure Description Bank
A2: Measure Line Item | B2: Measure Description
A3: Attic Insulation | B3: Upgrade existing attic insulation levels [of R-XX] to R-49 in accordance with applicable PNNL building science standards and program requirements to improve thermal performance, reduce energy consumption, and enhance occupant comfort. Work will include preparation of attic areas to support proper airflow, insulation depth consistency, and long-term system performance.
B4: Install eave baffles with 48-inch extensions in each accessible attic bay to maintain ventilation pathways and allow full insulation coverage above exterior wall top plates.
B5: Install insulation rulers in each attic bay on both sides to verify uniform insulation depth and ensure consistent installed R-values throughout the attic plane.
B6: Install blown-in fiberglass insulation to achieve a minimum final attic insulation value of R-49 across all accessible attic areas.
B7: Custom build and install insulated attic access hatches including insulation damming, insulated access covers, and weatherstripping to minimize thermal bypass and air leakage.
B8: All insulation materials and installation methods will comply with applicable code requirements, manufacturer specifications, and accepted energy efficiency best practices.
A11: Attic Air Sealing | B11: Perform attic air sealing to reduce uncontrolled air leakage between conditioned spaces and unconditioned attic areas in accordance with PNNL air barrier and weatherization best practices. Removal and disposal of existing insulation material will prepare the attic space for proper air sealing. Air sealing work will be completed prior to insulation installation to maximize thermal effectiveness and moisture control performance.
B12: Scope of work includes identification and sealing of accessible air leakage pathways including, but not limited to:
B13: Plumbing penetrations
B14: Electrical penetrations
B15: Top plates
B16: Mechanical and duct penetrations
B17: Soffits and open chases
B18: Attic access openings
B19: Miscellaneous bypasses and framing gaps
B20: Fabricated isolation boxes for exhaust fans and recessed lights
B21: Approved sealants, foam products, sheet materials, and weatherstripping will be utilized as appropriate for each application to improve building envelope tightness, reduce heating and cooling loads, and improve overall occupant comfort and building durability.
A23: Low Flow Devices: Bath Aerators | B23: Installation of low flow faucet aerators in tenant bathrooms for water and energy savings. Model: Niagara 0.5 GPM Aerator N3205N
A24: Low Flow Devices: Kitchen Aerators | B24: Installation of low flow faucet aerators in tenant kitchens for water and energy savings. Model: Niagara 0.5 GPM Aerator N3205N
A25: Low Flow Devices: Showerheads | B25: Installation of low flow handheld showerheads in tenant bathrooms for water and energy savings. Model: Niagara Earth Handheld Showerhead N2945CH
